<?xml version="1.0"?>
<robot xmlns:xacro="http://ros.org/wiki/xacro" name="soly">
  <xacro:include filename="$(find soly)/urdf/robot.gazebo"/>
  <xacro:include filename="$(find soly)/urdf/sensor.xacro"/>

  <link name="base_link">
    <inertial>
      <origin xyz="-0.0023666 -0.0061008 -0.0017152" rpy="0 0 0" />
      <mass value="3.1116" />
      <inertia ixx="0.030574" ixy="-0.0004163" ixz="-1.3976E-05" iyy="0.03032" iyz="-0.00015896" izz="0.055894" />
    </inertial>
    <visual>
      <origin xyz="0 0 0" rpy="0 0 0" />
      <geometry>
        <mesh filename="package://soly/meshes/base_link.STL" />
      </geometry>
      <material name="">
        <color rgba="0.274 0.509 0.705 1" />
      </material>
    </visual>
    <collision>
      <origin xyz="0 0 0" rpy="0 0 0" />
      <geometry>
        <mesh filename="package://soly/meshes/base_link.STL" />
      </geometry>
    </collision>
  </link>
  
  <link name="right_wheel_Link">
    <inertial>
      <origin xyz="0 -0.0075 0" rpy="0 0 0" />
      <mass value="0.054243838245486" />
      <inertia ixx="1.71160505001731E-05" ixy="-8.94718916174317E-22" ixz="-5.79682761060264E-21" 
               iyy="3.21979570661404E-05" iyz="8.02608461219266E-22" izz="1.7116050500173E-05" />
    </inertial>
    <visual>
      <origin xyz="0 0 0" rpy="0 0 0" />
      <geometry>
        <mesh filename="package://soly/meshes/right_wheel_Link.STL" />
      </geometry>
      <material name="">
        <color rgba="0.298 0.298 0.298 1" />
      </material>
    </visual>
    <collision>
      <origin xyz="0 0 0" rpy="0 0 0" />
      <geometry>
        <mesh filename="package://soly/meshes/right_wheel_Link.STL" />
      </geometry>
    </collision>
  </link>
  
  <joint name="right_wheel_joint" type="continuous">
    <origin xyz="-0.029871 0.15291 -0.034743" rpy="0 0 0" />
    <parent link="base_link" />
    <child link="right_wheel_Link" />
    <axis xyz="0 1 0" />
  </joint>
  
  <link name="left_wheel_link">
    <inertial>
      <origin xyz="-5.55E-17 0.0075 2.77E-17" rpy="0 0 0" />
      <mass value="0.054243838245486" />
      <inertia ixx="1.7116050500173E-05" ixy="4.71102933667598E-21" ixz="-6.16932141916073E-21" 
               iyy="3.21979570661404E-05" iyz="2.82263779720997E-21" izz="1.7116050500173E-05" />
    </inertial>
    <visual>
      <origin xyz="0 0 0" rpy="0 0 0" />
      <geometry>
        <mesh filename="package://soly/meshes/left_wheel_link.STL" />
      </geometry>
      <material name="">
        <color rgba="0.298 0.298 0.298 1" />
      </material>
    </visual>
    <collision>
      <origin xyz="0 0 0" rpy="0 0 0" />
      <geometry>
        <mesh filename="package://soly/meshes/left_wheel_link.STL" />
      </geometry>
    </collision>
  </link>
  
  <joint name="left_wheel_joint" type="continuous">
    <origin xyz="-0.029871 -0.16039 -0.034743" rpy="0 0 0" />
    <parent link="base_link" />
    <child link="left_wheel_link" />
    <axis xyz="0 -1 0" />
  </joint>
  
  <link name="link_1">
    <inertial>
      <origin xyz="0 0 0" rpy="0 0 0"/>
      <mass value="0.0286112"/>
      <inertia ixx="2.58e-06" ixy="0" ixz="0" iyy="2.58e-06" iyz="0" izz="2.58e-06"/>
    </inertial>
    <visual>
      <origin xyz="0 0 0" rpy="0 0 0"/>
      <geometry>
        <sphere radius="0.015"/>
      </geometry>
      <material name="Gazebo/Grey">
        <color rgba="0.7 0.7 0.7 1"/>
      </material>
    </visual>
    <collision>
      <origin xyz="0 0 0" rpy="0 0 0"/>
      <geometry>
        <sphere radius="0.015"/>
      </geometry>
    </collision>
  </link>
  
  <joint name="link_1_joint" type="continuous">
    <parent link="base_link"/>
    <child link="link_1"/>
    <origin xyz="0.186367 -0.001405 -0.055595" rpy="0.003639 0.025 0.147249"/>
  </joint>
</robot>
